Workbook

Sheet 道具主表
A1: ##var | B1: id | C1: name | D1: desc | E1: quality | F1: type | G1: tabs | H1: is_init_create | I1: specialEffect | J1: reward | K1: param | L1: weightSort | M1: is_hide | N1: resId | O1: stackLimit | P1: levelLimit | Q1: isAutoUse | R1: nameRich | S1: nameDesc
A2: ##var
A3: ##type | B3: int | C3: string | D3: string | E3: Item.Quality | F3: Item.Type | G3: Item.Tabs | H3: bool | I3: (list#sep=;),Property.PropertyData | J3: (list#sep=;),Prop.PropObj | K3: (list#sep=;),string | L3: int | M3: bool | N3: int#ref=Item.TbItemRes | O3: int | P3: int | Q3: bool | R3: string | S3: string
A4: ##group | I4: s | J4: s | N4: c
A5: ## | B5: id | C5: 备注 | D5: 物品描述 | E5: 品质 | F5: 类型 | G5: 页签 | H5: 是否初始化创建 | I5: 增加属性类型 | J5: 获得奖励 | K5: 参数 | L5: 排序权重 | M5: 是否在背包中隐藏 | N5: 资源表 | O5: 堆叠上限 0-无限 | P5: 使用等级 | Q5: 是否自动使用 | R5: 道具名富文本 | S5: 道具描述富文本
B6: 1 | C6: 修炼经验 | D6: 玩家经验 | E6: 1 | F6: 1 | G6: 1 | H6: 1 | L6: 1 | M6: 1 | N6: 1 | O6: 0 | P6: 0 | Q6: 0 | R6: ="<color=#"&VLOOKUP(E6,[1]品质主表!$B$6:$C$13,2,FALSE)&">"&C6&"</color>" -> <color=#18e71a>修炼经验</color> | S6: =R6 -> <color=#18e71a>修炼经验</color>
B7: 2 | C7: 阵法经验 | D7: 阵法经验 | E7: 1 | F7: 1 | G7: 1 | H7: 1 | L7: 1 | M7: 1 | N7: 2 | O7: 0 | P7: 0 | Q7: 0 | R7: ="<color=#"&VLOOKUP(E7,[1]品质主表!$B$6:$C$13,2,FALSE)&">"&C7&"</color>" -> <color=#18e71a>阵法经验</color> | S7: =R7 -> <color=#18e71a>阵法经验</color>
B8: 1001 | C8: 悟性丹 | D8: 每颗增加20点修炼值、50点攻击、2000点生命、1点悟性 | E8: 3 | F8: 2 | G8: 1 | H8: 1 | I8: 1,1,60;4,1,2400;29,1,20;31,1,1 | L8: 1001 | M8: 0 | N8: 1001 | O8: 0 | P8: 0 | Q8: 0 | R8: ="<color=#"&VLOOKUP(E8,[1]品质主表!$B$6:$C$13,2,FALSE)&">"&C8&"</color>" -> <color=#f044dc>悟性丹</color> | S8: =R8 -> <color=#f044dc>悟性丹</color>
B9: 1002 | C9: 突破丹 | D9: 突破时，每颗突破丹增加1%的突破成功概率，突破后会消耗对应的数量 | E9: 3 | F9: 3 | G9: 1 | H9: 1 | K9: 100 | L9: 1002 | M9: 0 | N9: 1002 | O9: 0 | P9: 0 | Q9: 0 | R9: ="<color=#"&VLOOKUP(E9,[1]品质主表!$B$6:$C$13,2,FALSE)&">"&C9&"</color>" -> <color=#f044dc>突破丹</color> | S9: =R9 -> <color=#f044dc>突破丹</color>
B10: 1003 | C10: 修炼丹 | D10: 修炼时，每次修炼提取100修炼经验，最多30000点 | E10: 3 | F10: 4 | G10: 1 | H10: 1 | K10: 100;30000 | L10: 1003 | M10: 0 | N10: 1003 | O10: 0 | P10: 0 | Q10: 0 | R10: ="<color=#"&VLOOKUP(E10,[1]品质主表!$B$6:$C$13,2,FALSE)&">"&C10&"</color>" -> <color=#f044dc>修炼丹</color> | S10: =R10 -> <color=#f044dc>修炼丹</color>
B11: 1004 | C11: 经验丹 | D11: 获得时直接提高30000点修炼经验 | E11: 3 | F11: 5 | G11: 1 | H11: 1 | J11: 1,1,30000 | L11: 1004 | M11: 0 | N11: 1004 | O11: 0 | P11: 0 | Q11: 1 | R11: ="<color=#"&VLOOKUP(E11,[1]品质主表!$B$6:$C$13,2,FALSE)&">"&C11&"</color>" -> <color=#f044dc>经验丹</color> | S11: =R11 -> <color=#f044dc>经验丹</color>
B12: 1005 | C12: 强化石 | D12: 法宝强化道具 | E12: 3 | F12: 6 | G12: 1 | H12: 1 | L12: 1005 | M12: 0 | N12: 1005 | O12: 0 | P12: 0 | Q12: 0 | R12: ="<color=#"&VLOOKUP(E12,[1]品质主表!$B$6:$C$13,2,FALSE)&">"&C12&"</color>" -> <color=#f044dc>强化石</color> | S12: =R12 -> <color=#f044dc>强化石</color>
B13: 1006 | C13: 幽冥钢 | D13: 攻击法宝进阶道具 | E13: 3 | F13: 6 | G13: 1 | H13: 1 | I13: 1,1,10 | L13: 1006 | M13: 0 | N13: 1006 | O13: 0 | P13: 0 | Q13: 0 | R13: ="<color=#"&VLOOKUP(E13,[1]品质主表!$B$6:$C$13,2,FALSE)&">"&C13&"</color>" -> <color=#f044dc>幽冥钢</color> | S13: =R13 -> <color=#f044dc>幽冥钢</color>
B14: 1007 | C14: 金刚砂 | D14: 防御法宝进阶道具 | E14: 3 | F14: 6 | G14: 1 | H14: 1 | I14: 4,1,400 | L14: 1007 | M14: 0 | N14: 1007 | O14: 0 | P14: 0 | Q14: 0 | R14: ="<color=#"&VLOOKUP(E14,[1]品质主表!$B$6:$C$13,2,FALSE)&">"&C14&"</color>" -> <color=#f044dc>金刚砂</color> | S14: =R14 -> <color=#f044dc>金刚砂</color>
B15: 1008 | C15: 星辰铁 | D15: 坐骑强化道具 | E15: 3 | F15: 6 | G15: 1 | H15: 1 | L15: 1008 | M15: 0 | N15: 1008 | O15: 0 | P15: 0 | Q15: 0 | R15: ="<color=#"&VLOOKUP(E15,[1]品质主表!$B$6:$C$13,2,FALSE)&">"&C15&"</color>" -> <color=#f044dc>星辰铁</color> | S15: =R15 -> <color=#f044dc>星辰铁</color>
B16: 1009 | C16: 五色石 | D16: 坐骑进阶道具 | E16: 3 | F16: 6 | G16: 1 | H16: 1 | I16: 1,1,10;4,1,400 | L16: 1009 | M16: 0 | N16: 1009 | O16: 0 | P16: 0 | Q16: 0 | R16: ="<color=#"&VLOOKUP(E16,[1]品质主表!$B$6:$C$13,2,FALSE)&">"&C16&"</color>" -> <color=#f044dc>五色石</color> | S16: =R16 -> <color=#f044dc>五色石</color>
B17: 1010 | C17: 重生符 | D17: 在本宗门主场景死亡后会自动复活，宗门战时不生效 | E17: 3 | F17: 14 | G17: 1 | H17: 1 | L17: 1010 | M17: 0 | N17: 1010 | O17: 0 | P17: 0 | Q17: 0 | R17: ="<color=#"&VLOOKUP(E17,[1]品质主表!$B$6:$C$13,2,FALSE)&">"&C17&"</color>" -> <color=#f044dc>重生符</color> | S17: =R17 -> <color=#f044dc>重生符</color>
B18: 1011 | C18: 神通碎片 | D18: 粉色品质功法分解而得 | E18: 3 | F18: 6 | G18: 1 | H18: 1 | L18: 1011 | M18: 0 | N18: 1011 | O18: 0 | P18: 0 | Q18: 0 | R18: ="<color=#"&VLOOKUP(E18,[1]品质主表!$B$6:$C$13,2,FALSE)&">"&C18&"</color>" -> <color=#f044dc>神通碎片</color> | S18: =R18 -> <color=#f044dc>神通碎片</color>
B19: 1012 | C19: 乾坤袋 | D19: 可以开出各种道具，甚至有稀有的皮肤 | E19: 3 | F19: 12 | G19: 1 | H19: 1 | K19: 240 | L19: 1012 | M19: 0 | N19: 1012 | O19: 0 | P19: 0 | Q19: 1 | R19: ="<color=#"&VLOOKUP(E19,[1]品质主表!$B$6:$C$13,2,FALSE)&">"&C19&"</color>" -> <color=#f044dc>乾坤袋</color> | S19: =R19 -> <color=#f044dc>乾坤袋</color>
B20: 1013 | C20: 礼物1 | D20: 使用后赠送1次礼物1 | E20: 3 | F20: 13 | G20: 1 | H20: 1 | K20: 11582 | L20: 1013 | M20: 0 | N20: 1013 | O20: 0 | P20: 0 | Q20: 0 | R20: ="<color=#"&VLOOKUP(E20,[1]品质主表!$B$6:$C$13,2,FALSE)&">"&C20&"</color>" -> <color=#f044dc>礼物1</color> | S20: =R20 -> <color=#f044dc>礼物1</color>
B21: 1014 | C21: 礼物2 | D21: 使用后赠送1次礼物2 | E21: 3 | F21: 13 | G21: 1 | H21: 1 | K21: 11584 | L21: 1014 | M21: 0 | N21: 1014 | O21: 0 | P21: 0 | Q21: 0 | R21: ="<color=#"&VLOOKUP(E21,[1]品质主表!$B$6:$C$13,2,FALSE)&">"&C21&"</color>" -> <color=#f044dc>礼物2</color> | S21: =R21 -> <color=#f044dc>礼物2</color>
B22: 1015 | C22: 礼物4 | D22: 使用后赠送1次礼物4 | E22: 3 | F22: 13 | G22: 1 | H22: 1 | K22: 11606 | L22: 1016 | M22: 0 | N22: 1015 | O22: 0 | P22: 0 | Q22: 0 | R22: ="<color=#"&VLOOKUP(E22,[1]品质主表!$B$6:$C$13,2,FALSE)&">"&C22&"</color>" -> <color=#f044dc>礼物4</color> | S22: =R22 -> <color=#f044dc>礼物4</color>
B23: 1016 | C23: 礼物5 | D23: 使用后赠送1次礼物5 | E23: 3 | F23: 13 | G23: 1 | H23: 1 | K23: 11585 | L23: 1017 | M23: 0 | N23: 1016 | O23: 0 | P23: 0 | Q23: 0 | R23: ="<color=#"&VLOOKUP(E23,[1]品质主表!$B$6:$C$13,2,FALSE)&">"&C23&"</color>" -> <color=#f044dc>礼物5</color> | S23: =R23 -> <color=#f044dc>礼物5</color>
B24: 1017 | C24: 礼物6 | D24: 使用后赠送1次礼物6 | E24: 3 | F24: 13 | G24: 1 | H24: 1 | K24: 11586 | L24: 1018 | M24: 0 | N24: 1017 | O24: 0 | P24: 0 | Q24: 0 | R24: ="<color=#"&VLOOKUP(E24,[1]品质主表!$B$6:$C$13,2,FALSE)&">"&C24&"</color>" -> <color=#f044dc>礼物6</color> | S24: =R24 -> <color=#f044dc>礼物6</color>
B25: 1018 | C25: 礼物7 | D25: 使用后赠送1次礼物7 | E25: 3 | F25: 13 | G25: 1 | H25: 1 | K25: 11587 | L25: 1019 | M25: 0 | N25: 1018 | O25: 0 | P25: 0 | Q25: 0 | R25: ="<color=#"&VLOOKUP(E25,[1]品质主表!$B$6:$C$13,2,FALSE)&">"&C25&"</color>" -> <color=#f044dc>礼物7</color> | S25: =R25 -> <color=#f044dc>礼物7</color>
B26: 1019 | C26: 礼物8 | D26: 使用后赠送1次礼物8 | E26: 3 | F26: 13 | G26: 1 | H26: 1 | K26: 11590 | L26: 1020 | M26: 0 | N26: 1019 | O26: 0 | P26: 0 | Q26: 0 | R26: ="<color=#"&VLOOKUP(E26,[1]品质主表!$B$6:$C$13,2,FALSE)&">"&C26&"</color>" -> <color=#f044dc>礼物8</color> | S26: =R26 -> <color=#f044dc>礼物8</color>
B27: 1020 | C27: 礼物3 | D27: 使用后赠送1次礼物3 | E27: 3 | F27: 13 | G27: 1 | H27: 1 | K27: 12252 | L27: 1015 | M27: 0 | N27: 1020 | O27: 0 | P27: 0 | Q27: 0 | R27: ="<color=#"&VLOOKUP(E27,[1]品质主表!$B$6:$C$13,2,FALSE)&">"&C27&"</color>" -> <color=#f044dc>礼物3</color> | S27: =R27 -> <color=#f044dc>礼物3</color>
B28: 1030 | C28: 灵石 | D28: 水系宠物碎片分解而来 | E28: 3 | F28: 15 | G28: 4 | H28: 1 | L28: 1030 | M28: 0 | N28: 1030 | O28: 0 | P28: 0 | Q28: 0 | R28: ="<color=#"&VLOOKUP(E28,[1]品质主表!$B$6:$C$13,2,FALSE)&">"&C28&"</color>" -> <color=#f044dc>灵石</color> | S28: =R28 -> <color=#f044dc>灵石</color>
B29: 1031 | C29: 幼蛇碎片 | D29: 幼蛇碎片 | E29: 3 | F29: 15 | G29: 4 | H29: 1 | L29: 1031 | M29: 0 | N29: 1031 | O29: 0 | P29: 0 | Q29: 0 | R29: ="<color=#"&VLOOKUP(E29,[1]品质主表!$B$6:$C$13,2,FALSE)&">"&C29&"</color>" -> <color=#f044dc>幼蛇碎片</color> | S29: =R29 -> <color=#f044dc>幼蛇碎片</color>
B30: 1040 | C30: 攻元丹 | D30: 每颗增加宠物40点攻击 | E30: 3 | F30: 15 | G30: 4 | H30: 1 | I30: 1,1,40 | L30: 1040 | M30: 0 | N30: 1040 | O30: 0 | P30: 0 | Q30: 0 | R30: ="<color=#"&VLOOKUP(E30,[1]品质主表!$B$6:$C$13,2,FALSE)&">"&C30&"</color>" -> <color=#f044dc>攻元丹</color> | S30: =R30 -> <color=#f044dc>攻元丹</color>
B31: 1041 | C31: 命元丹 | D31: 每颗增加宠物1600点生命 | E31: 3 | F31: 15 | G31: 4 | H31: 1 | I31: 4,1,1600 | L31: 1041 | M31: 0 | N31: 1041 | O31: 0 | P31: 0 | Q31: 0 | R31: ="<color=#"&VLOOKUP(E31,[1]品质主表!$B$6:$C$13,2,FALSE)&">"&C31&"</color>" -> <color=#f044dc>命元丹</color> | S31: =R31 -> <color=#f044dc>命元丹</color>
B32: 1042 | C32: 淬炼石 | D32: 宠物装备强化道具 | E32: 3 | F32: 15 | G32: 4 | H32: 1 | L32: 1042 | M32: 0 | N32: 1042 | O32: 0 | P32: 0 | Q32: 0 | R32: ="<color=#"&VLOOKUP(E32,[1]品质主表!$B$6:$C$13,2,FALSE)&">"&C32&"</color>" -> <color=#f044dc>淬炼石</color> | S32: =R32 -> <color=#f044dc>淬炼石</color>
B33: 1043 | C33: 砺石珠 | D33: 宠物装备进阶道具 | E33: 3 | F33: 15 | G33: 4 | H33: 1 | L33: 1043 | M33: 0 | N33: 1043 | O33: 0 | P33: 0 | Q33: 0 | R33: ="<color=#"&VLOOKUP(E33,[1]品质主表!$B$6:$C$13,2,FALSE)&">"&C33&"</color>" -> <color=#f044dc>砺石珠</color> | S33: =R33 -> <color=#f044dc>砺石珠</color>
B34: 1050 | C34: 凤凰皮肤碎片 | D34: 凤凰皮肤碎片 | E34: 7 | F34: 18 | G34: 1 | H34: 1 | L34: 1050 | M34: 0 | N34: 1050 | O34: 0 | P34: 0 | Q34: 0 | R34: ="<color=#"&VLOOKUP(E34,[1]品质主表!$B$6:$C$13,2,FALSE)&">"&C34&"</color>" -> <color=#ff779d>凤凰皮肤碎片</color> | S34: =R34 -> <color=#ff779d>凤凰皮肤碎片</color>
B35: 1051 | C35: 凤凰坐骑碎片 | D35: 凤凰坐骑碎片 | E35: 7 | F35: 18 | G35: 1 | H35: 1 | L35: 1051 | M35: 0 | N35: 1051 | O35: 0 | P35: 0 | Q35: 0 | R35: ="<color=#"&VLOOKUP(E35,[1]品质主表!$B$6:$C$13,2,FALSE)&">"&C35&"</color>" -> <color=#ff779d>凤凰坐骑碎片</color> | S35: =R35 -> <color=#ff779d>凤凰坐骑碎片</color>
B36: 1061 | C36: 灵宝碎片 | D36: 灵宝碎片 | E36: 3 | F36: 18 | G36: 1 | H36: 1 | L36: 1061 | M36: 0 | N36: 1061 | O36: 0 | P36: 0 | Q36: 0 | R36: ="<color=#"&VLOOKUP(E36,[1]品质主表!$B$6:$C$13,2,FALSE)&">"&C36&"</color>" -> <color=#f044dc>灵宝碎片</color> | S36: =R36 -> <color=#f044dc>灵宝碎片</color>
B37: 1062 | C37: 攻击灵宝 | D37: 攻击灵宝 | E37: 3 | F37: 19 | G37: 2 | H37: 1 | I37: 1,3,100 | L37: 1062 | M37: 0 | N37: 1062 | O37: 0 | P37: 0 | Q37: 0 | R37: ="<color=#"&VLOOKUP(E37,[1]品质主表!$B$6:$C$13,2,FALSE)&">"&C37&"</color>" -> <color=#f044dc>攻击灵宝</color> | S37: =R37 -> <color=#f044dc>攻击灵宝</color>
B38: 1063 | C38: 生命灵宝 | D38: 生命灵宝 | E38: 3 | F38: 19 | G38: 3 | H38: 1 | I38: 4,3,100 | L38: 1063 | M38: 0 | N38: 1063 | O38: 0 | P38: 0 | Q38: 0 | R38: ="<color=#"&VLOOKUP(E38,[1]品质主表!$B$6:$C$13,2,FALSE)&">"&C38&"</color>" -> <color=#f044dc>生命灵宝</color> | S38: =R38 -> <color=#f044dc>生命灵宝</color>
B39: 1064 | C39: 乾坤袋 | D39: 可以开出各种道具，甚至有稀有的皮肤 | E39: 3 | F39: 2 | G39: 1 | H39: 1 | J39: 1,1012,1 | L39: 1064 | M39: 0 | N39: 1064 | O39: 0 | P39: 0 | Q39: 0 | R39: ="<color=#"&VLOOKUP(E39,[1]品质主表!$B$6:$C$13,2,FALSE)&">"&C39&"</color>" -> <color=#f044dc>乾坤袋</color> | S39: =R39 -> <color=#f044dc>乾坤袋</color>
B40: 2013 | C40: 礼物1 | D40: 使用后赠送1次礼物1 | E40: 3 | F40: 13 | G40: 1 | H40: 1 | K40: n1/Dg1905sj1FyoBlQBvmbaDZFBNaKuKZH6zxHkv8Lg5x2cRfrKUTb8gzMs= | L40: 1013 | M40: 0 | N40: 2013 | O40: 0 | P40: 0 | Q40: 0 | R40: ="<color=#"&VLOOKUP(E40,[1]品质主表!$B$6:$C$13,2,FALSE)&">"&C40&"</color>" -> <color=#f044dc>礼物1</color> | S40: =R40 -> <color=#f044dc>礼物1</color>
...

Sheet 道具资源表
A1: ##var | B1: id | C1: ## | D1: ## | E1: icon | F1: bigIcon
A2: ##var
A3: ##type | B3: int | E3: string | F3: string
A4: ##group
A5: ## | B5: id | C5: 名字 | D5: 描述 | E5: 道具图标128*128 | F5: 道具图标512*512
B6: 1 | C6: 玩家经验 | D6: 玩家经验
B7: 2 | C7: 灵兽经验 | D7: 灵兽经验
B8: 1001 | C8: 悟性丹 | D8: 每颗悟性丹增加20点修炼值、50点攻击、3000点生命 | E8: GoodsIcon/Icon_1001
B9: 1002 | C9: 突破丹 | D9: 突破时，每颗突破丹增加1%的突破成功概率，突破后会消耗对应的数量 | E9: GoodsIcon/Icon_1002
B10: 1003 | C10: 修炼丹 | D10: 修炼时，每次修炼提取100修炼经验，最多30000点 | E10: GoodsIcon/Icon_1003
B11: 1004 | C11: 洗髓丹 | D11: 获得时直接提高30000点修炼经验 | E11: GoodsIcon/Icon_1004
B12: 1005 | C12: 强化石 | D12: 法宝强化道具 | E12: GoodsIcon/Icon_1005
B13: 1006 | C13: 幽冥钢 | D13: 攻击法宝进阶道具 | E13: GoodsIcon/Icon_1006
B14: 1007 | C14: 金刚砂 | D14: 防御法宝进阶道具 | E14: GoodsIcon/Icon_1007
B15: 1008 | C15: 星辰铁 | D15: 坐骑强化道具 | E15: GoodsIcon/Icon_1008
B16: 1009 | C16: 五色石 | D16: 坐骑进阶道具 | E16: GoodsIcon/Icon_1009
B17: 1010 | C17: 重生符 | D17: 在本宗门主场景死亡后会自动复活，宗门战时不生效 | E17: GoodsIcon/Icon_1010
B18: 1011 | C18: 神通碎片 | D18: 粉色品质功法分解而得 | E18: GoodsIcon/Icon_1011
B19: 1012 | C19: 仙缘宝盒 | D19: 可以开出各种道具，甚至有稀有的皮肤 | E19: GoodsIcon/Icon_1009
... B226: 15201 | C226: 烈焰护盾 | D226: 烈焰护盾 | E226: GoodsIcon/Icon_10401
B227: 20001 | C227: 男境界1 | D227: 男境界1
B228: 20002 | C228: 男境界2 | D228: 男境界2
B229: 20003 | C229: 男境界3 | D229: 男境界3
B230: 20004 | C230: 男境界4 | D230: 男境界4
B231: 20005 | C231: 男境界5 | D231: 男境界5
B232: 20006 | C232: 男境界6 | D232: 男境界6
B233: 20011 | C233: 浩然仙宗（男-1天） | D233: 浩然仙宗（男-1天）
B234: 20012 | C234: 浩然仙宗（男-3天） | D234: 浩然仙宗（男-3天）
B235: 20013 | C235: 浩然仙宗（男-5天） | D235: 浩然仙宗（男-5天）
B236: 20014 | C236: 火舞凤皇（男-1天） | D236: 火舞凤皇（男-1天）
B237: 20015 | C237: 蝶舞霓裳（男） | D237: 蝶舞霓裳（男）
B238: 20101 | C238: 男进度1-法宝粉 | D238: 男进度1-法宝粉
... B285: 28003 | C285: 真仙至尊 | D285: 真仙至尊
B286: 30001 | C286: 寒冰剑 | E286: GoodsIcon/Icon_30001
B287: 30002 | C287: 雷霆锤 | E287: GoodsIcon/Icon_30002
B288: 30003 | C288: 紫电刀 | E288: GoodsIcon/Icon_30003
B289: 30004 | C289: 禅心拂 | E289: GoodsIcon/Icon_30004
B290: 30005 | C290: 烈焰枪 | E290: GoodsIcon/Icon_30005
B291: 30006 | C291: 苍龙爪 | E291: GoodsIcon/Icon_30006
B292: 30007 | C292: 云篆笔 | E292: GoodsIcon/Icon_30007
...

Sheet 道具合成表
A1: ##var | B1: id | C1: ## | D1: ## | E1: composeMax | F1: shardNum | G1: reward | H1: drop
A2: ##var
A3: ##type | B3: int | C3: string | D3: string | E3: int | F3: int | G3: (list#sep=;),Prop.PropObj | H3: int
A4: ##group | G4: s
A5: ## | B5: id | C5: 备注 | D5: 物品描述 | E5: 最多合成数量 | F5: 需要数量 | G5: 获得奖励 | H5: 随机奖励
B6: 1050 | C6: 凤凰皮肤碎片 | D6: 凤凰皮肤碎片 | E6: 1 | F6: 100 | G6: 2,20901,1;2,21901,1 | H6: 0
B7: 1051 | C7: 凤凰坐骑碎片 | D7: 凤凰坐骑碎片 | E7: 1 | F7: 100 | G7: 5,41001,1 | H7: 0
B8: 1011 | C8: 神通碎片 | D8: 粉色品质功法分解而得 | E8: 0 | F8: 100 | H8: 3010001
B9: 1061 | C9: 灵宝碎片 | D9: 灵宝碎片 | E9: 0 | F9: 100 | H9: 3010002
